<?xml version="1.0" encoding="utf-8"?>
<mujoco model="inverted_pendulum">
    <compiler angle="radian" meshdir="meshes" autolimits="true" />
    <option timestep="0.002" gravity="0 0 -9.81" wind="0 0 0" integrator="implicitfast"
        density="1.225"
        viscosity="1.8e-5" />

    <visual>
        <global realtime="1" />
        <quality shadowsize="16384" numslices="28" offsamples="4" />
        <headlight diffuse="1 1 1" specular="0.5 0.5 0.5" active="1" />
        <rgba fog="1 0 0 1" haze="1 1 1 1" />
    </visual>

    <asset>
        <!-- <texture type="skybox" file="../asset/desert.png"
            gridsize="3 4" gridlayout=".U..LFRB.D.." /> -->
        <texture name="plane" type="2d" builtin="checker" rgb1=".1 .1 .1" rgb2=".9 .9 .9"
            width="512" height="512" mark="cross" markrgb=".8 .8 .8" />
        <material name="plane" reflectance="0.3" texture="plane" texrepeat="1 1" texuniform="true" />
        <material name="box" rgba="0 0.5 0 1" emission="0" />
    </asset>

    <default>
        <geom solref=".5e-4" solimp="0.9 0.99 1e-4" fluidcoef="0.5 0.25 0.5 2.0 1.0" />
        <site size="0.04" group="2" rgba="1 0.1 0.5 0.5" />
        <default class="muscle">
            <site size="0.015" group="2" rgba="1 0.1 0.1 0.5"/>
            <tendon rgba="0.95 0.3 0.3 41" width="0.002"/>
        </default>
    </default>

    <tendon>
    <spatial class="muscle" name="tendon1" >
      <site site="muscle_site_1"/>
      <!-- <geom geom="Elbow_PT_ECRL_wrap" sidesite="Elbow_PT_ECRL_site_ECRL_side"></geom> -->
      <site site="muscle_site_2"/>
      <site site="muscle_site_3"/>
      <!-- <geom geom="ECRL_torus_wrap" sidesite="ECRL_torus_site_ECRL_side"/> -->
      <site site="muscle_site_4"/>
      <site site="muscle_site_5"/>
      <site site="muscle_site_6"/>
      <site site="muscle_site_end"/>
    </spatial>
    </tendon>
    <worldbody>
        <geom name="floor" pos="0 0 0" size="10 10 .1" type="plane" material="plane"
            condim="3" />
        <light directional="true" ambient=".3 .3 .3" pos="30 30 30" dir="0 -2 -1"
            diffuse=".5 .5 .5" specular=".5 .5 .5" />
        
        <body name="support" pos="0 0 0.5">
            <geom type="cylinder" mass="100" size="0.01 0.5" rgba="0.2 0.2 0.2 1"/>
            <site name="muscle_site_1" class="muscle" pos="-0.02 0 0.6"/>
            
            <body name="rotay_am" pos="0 0 0.51">
                <joint type="hinge" name="joint1" pos="0 0 0" axis="0 0 1" damping="0.001"
                    frictionloss="0.0" stiffness="0.5"/>
                <geom type="capsule" mass="0.01" fromto="0 0 0 0.2 0 0" size="0.01"
                    rgba="0.8 0.2 0.2 0.5"/>
                <site name="muscle_site_2" class="muscle" pos="0.03 -0.02 0.1"/>
                <site name="muscle_site_3" class="muscle" pos="0.18 -0.02 0.1"/>
                <body name="pendulum" pos="0.2 0 0">
                    <joint type="hinge" name="joint2" pos="0 0 0" axis="1 0 0" damping="0.001"
                        frictionloss="0.0" />
                    <geom type="capsule" mass="0.005" fromto="0 0 0 0 0 -0.3" size="0.01"
                        rgba="0.8 0.2 0.2 1" />
                    <site name="muscle_site_4" class="muscle" pos="0.03 -0.02 0.0"/>
                    <site name="muscle_site_5" class="muscle" pos="0.02 -0.02 -0.27"/>
                    <geom type="sphere" mass="0.01" size="0.03" pos="0 0 -0.3" rgba="0.2 0.8 0.2 1" />
                    <body name="pendulum2" pos="0 0 -0.3">
                        <joint type="hinge" name="joint3" pos="0 0 0" axis="1 0 0" damping="0.001"
                        frictionloss="0.0" />
                        <geom type="capsule" mass="0.005" fromto="0 0 0 0 0 -0.2" size="0.01"
                        rgba="0.8 0.2 0.2 1" />
                        <site name="muscle_site_6" class="muscle" pos="0.02 -0.02 -0.02"/>
                        <site name="site1" pos="0 0 -0.2" />
                    </body>
                </body>
            </body>
        </body>
        <body name="ball" pos="0.22 0 0.3">
            <joint type="free" name="freejoint" pos="0 0 0" damping="0.001"
            frictionloss="0.0" />
            <geom type="sphere" mass="0.1" size="0.1" pos="0 0 -0" rgba="0.2 0.8 0.2 1" />
            <site name="muscle_site_end" class="muscle" pos="0 0 0.035"/>
        </body>
    </worldbody>
    <actuator>
        <muscle name="muscle1" force="10" class="muscle" tendon="tendon1" lengthrange="0.875 1.025"/>
    </actuator>


</mujoco>